<?xml version="1.0" encoding="utf-8"?>
<robot xmlns:xacro="http://www.ros.org/wiki/xacro">
    <xacro:property name="PI" value = "3.1415926"/>

    <link name="right_brush">
        <inertial>
            <origin xyz="0 0 0.0164" rpy="0 0 0" />

            <!-- <mass value="1.6765" /> -->
            <mass value="16.765" />

            <inertia ixx="0.0122" ixy="0" ixz="0" iyy="0.0122" iyz="0" izz="0.0231" />
        </inertial>
        <visual>
            <origin xyz="0 0 0" rpy="0 0 0" />
            <geometry>
                <mesh filename="package://cleaningrobot_description/meshes/right_brush.STL" />
            </geometry>
            <xacro:color_material color="black"/>
        </visual>
        <collision>
            <origin xyz="0 0 0" rpy="0 0 0" />
            <geometry>
                <mesh filename="package://cleaningrobot_description/meshes/right_brush.STL" />
            </geometry>
        </collision>
    </link>
    <joint name="base_link2right_brush" type="continuous">
        <origin xyz="0.5260 -0.377 -0.3744" rpy="${PI} 0 ${PI/2}" />
        <parent link="base_link" />
        <child link="right_brush" />
        <axis xyz="0 0 1" />
    </joint>
    <gazebo reference="right_brush">
        <material>Gazebo/Black</material>
    </gazebo>
</robot>