<?xml version="1.0" encoding="utf-8"?>
<robot xmlns:xacro="http://www.ros.org/wiki/xacro">
    <xacro:property name="PI" value = "3.1415926"/>

    <link name="front_link">
        <inertial>
            <origin xyz="0 0 0.1380" rpy="0 0 0" />
            <mass value="0.6742" />
            <inertia ixx="0.0016" ixy="0" ixz="0" iyy="0.0021" iyz="0" izz="0.0011" />
        </inertial>
        <visual>
            <origin xyz="0 0 0" rpy="0 0 0" />
            <geometry>
                <mesh filename="package://robot_description/meshes/front_link.STL" />
            </geometry>
            <xacro:color_material color="yellow"/>
        </visual>
        <collision>
            <origin xyz="0 0 0" rpy="0 0 0" />
            <geometry>
                <mesh filename="package://robot_description/meshes/front_link.STL" />
            </geometry>
        </collision>
    </link>
    <joint name="base_link2front_link" type="revolute">
        <origin xyz="0.55 0 -0.1467" rpy="${-PI} 0 0" />
        <parent link="base_link" />
        <child link="front_link" />
        <axis xyz="0 0 1" />
        <limit lower="0" upper="0" effort="10" velocity="3" />
    </joint>


    <link name="front_wheel">
        <inertial>
            <origin xyz="0 0 0" rpy="0 0 0" />
            <mass value="2.6850" />
            <inertia ixx="0.01420" ixy="0" ixz="0" iyy="0.0260" iyz="0" izz="0.0142" />
        </inertial>
        <visual>
            <origin xyz="0 0 0" rpy="0 0 0" />
            <geometry>
                <mesh filename="package://robot_description/meshes/front_wheel.STL" />
            </geometry>
            <xacro:color_material color="red"/>
        </visual>
        <collision>
            <origin xyz="0 0 0" rpy="0 0 0" />
            <geometry>
                <mesh filename="package://robot_description/meshes/front_wheel.STL" />
            </geometry>
        </collision>
    </link>
    <joint name="front_wheel_joint" type="continuous">
        <origin xyz="0 0 0.26695" rpy="0 ${PI/2} 0" />
        <parent link="front_link" />
        <child link="front_wheel" />
        <axis xyz="0 -0.9984 0.056559" />
        <limit effort="100" velocity="100"/>
        <safety_controller k_velocity="10" />
    </joint>
    <gazebo reference="front_wheel">
        <mu1 value="0"/>
        <mu2 value="0"/>
    </gazebo>
    <gazebo reference="front_link">
        <material>Gazebo/Yellow</material>
    </gazebo>
</robot>