<?xml version="1.0" encoding="utf-8"?>
<robot xmlns:xacro="http://www.ros.org/wiki/xacro">
    <xacro:property name="PI" value = "3.1415926"/>

    <link name="left_wheel">
        <inertial>
            <origin xyz="0 0 0" rpy="0 0 0" />
            <mass value="3.2115" />
            <!-- <mass value="10" /> -->
            <inertia ixx="0.0150" ixy="0" ixz="0" iyy="0.0150" iyz="0" izz="0.0275" />
        </inertial>
        <visual>
            <origin xyz="0 0 0" rpy="0 0 0" />
            <geometry>
                <mesh filename="package://robot_description/meshes/left_wheel.STL" />
            </geometry>
            <xacro:color_material color="red"/>
        </visual>
        <collision>
            <origin xyz="0 0 0" rpy="0 0 0" />
            <geometry>
                <mesh filename="package://robot_description/meshes/left_wheel.STL" />
            </geometry>
        </collision>
    </link>
    <joint name="rear_left_wheel_joint" type="continuous">
        <origin xyz="-0.2865 0.403 -0.41363" rpy="${PI/2} 0 0" />
        <parent link="base_link" />
        <child link="left_wheel" />
        <axis xyz="0 0 -1" />
    </joint>
    <transmission name="left_wheel_joint_trans">
        <type>transmission_interface/SimpleTransmission</type>
        <actuator name="left_wheel_joint_motor">
            <mechanicalReduction>1</mechanicalReduction>
            <hardwareInterface>hardware_interface/VelocityJointInterface</hardwareInterface>
        </actuator>
        <joint name="rear_left_wheel_joint">
            <hardwareInterface>hardware_interface/VelocityJointInterface</hardwareInterface>
        </joint>
    </transmission>
    <gazebo reference="left_wheel">
        <material>Gazebo/Red</material>
        <mu1>200</mu1>
        <mu2>200</mu2>
        <fdir1>1 0 0</fdir1>
        <kp value="10000000.0"/>
        <kd value="1.0"/>
    </gazebo>
</robot>